Time slot   0
ld_routine
Time slot   1
	Loaded a process at input/proc/p1s, PID: 1 PRIO: 15
	CPU 3: Dispatched process  1
Time slot   2
Time slot   3
	CPU 3: Put process  1 to run queue
	CPU 3: Dispatched process  1
Time slot   4
Time slot   5
	Loaded a process at input/proc/m0s, PID: 2 PRIO: 120
	CPU 3: Put process  1 to run queue
	CPU 3: Dispatched process  1
	CPU 1: Dispatched process  2
liballoc:187
print_pgtbl (PID 2):
 PDG=7ee47c005080 P4g=7ee474000b90 PUD=7ee474001ba0 PMD=7ee474002bb0
Time slot   6
liballoc:187
print_pgtbl (PID 2):
 PDG=7ee47c005080 P4g=7ee474000b90 PUD=7ee474001ba0 PMD=7ee474002bb0
Time slot   7
	Loaded a process at input/proc/p0s, PID: 3 PRIO: 130
	CPU 1: Put process  2 to run queue
	CPU 1: Dispatched process  2
libfree:218
print_pgtbl (PID 2):
 PDG=7ee47c005080 P4g=7ee474000b90 PUD=7ee474001ba0 PMD=7ee474002bb0
	CPU 3: Put process  1 to run queue
	CPU 3: Dispatched process  1
Time slot   8
	CPU 0: Dispatched process  3
liballoc:187
print_pgtbl (PID 2):
 PDG=7ee47c005080 P4g=7ee474000b90 PUD=7ee474001ba0 PMD=7ee474002bb0
Time slot   9
	Loaded a process at input/proc/s0, PID: 4 PRIO: 38
	CPU 1: Put process  2 to run queue
	CPU 1: Dispatched process  4
	CPU 3: Put process  1 to run queue
	CPU 3: Dispatched process  1
	CPU 2: Dispatched process  2
liballoc:187
print_pgtbl (PID 3):
 PDG=7ee47c007b60 P4g=7ee478000b90 PUD=7ee478001ba0 PMD=7ee478002bb0
libwrite:529
print_pgtbl (PID 2):
 PDG=7ee47c005080 P4g=7ee474000b90 PUD=7ee474001ba0 PMD=7ee474002bb0
Time slot  10
	CPU 0: Put process  3 to run queue
	CPU 0: Dispatched process  3
liballoc:187
print_pgtbl (PID 3):
 PDG=7ee47c007b60 P4g=7ee478000b90 PUD=7ee478001ba0 PMD=7ee478002bb0
libwrite:529
print_pgtbl (PID 2):
 PDG=7ee47c005080 P4g=7ee474000b90 PUD=7ee474001ba0 PMD=7ee474002bb0
Time slot  11
libfree:218
print_pgtbl (PID 3):
 PDG=7ee47c007b60 P4g=7ee478000b90 PUD=7ee478001ba0 PMD=7ee478002bb0
	CPU 1: Put process  4 to run queue
	CPU 1: Dispatched process  4
	CPU 3: Put process  1 to run queue
	CPU 3: Dispatched process  1
	CPU 2: Processed  2 has finished
	Loaded a process at input/proc/s3, PID: 5 PRIO: 39
Time slot  12
	CPU 0: Put process  3 to run queue
	CPU 0: Dispatched process  5
	CPU 2: Dispatched process  3
liballoc:187
print_pgtbl (PID 3):
 PDG=7ee47c007b60 P4g=7ee478000b90 PUD=7ee478001ba0 PMD=7ee478002bb0
Time slot  13
libwrite:529
print_pgtbl (PID 3):
 PDG=7ee47c007b60 P4g=7ee478000b90 PUD=7ee478001ba0 PMD=7ee478002bb0
	CPU 1: Put process  4 to run queue
	CPU 1: Dispatched process  4
	CPU 3: Put process  1 to run queue
	CPU 3: Dispatched process  1
Time slot  14
	CPU 0: Put process  5 to run queue
	CPU 0: Dispatched process  5
	CPU 2: Put process  3 to run queue
	CPU 2: Dispatched process  3
libread:473
print_pgtbl (PID 3):
 PDG=7ee47c007b60 P4g=7ee478000b90 PUD=7ee478001ba0 PMD=7ee478002bb0
	Loaded a process at input/proc/m1s, PID: 6 PRIO: 15
Time slot  15
	CPU 1: Put process  4 to run queue
	CPU 1: Dispatched process  6
liballoc:187
print_pgtbl (PID 6):
 PDG=7ee47c00fb30 P4g=7ee474004c90 PUD=7ee474005ca0 PMD=7ee474006cb0
	CPU 3: Put process  1 to run queue
	CPU 3: Dispatched process  1
libwrite:529
print_pgtbl (PID 3):
 PDG=7ee47c007b60 P4g=7ee478000b90 PUD=7ee478001ba0 PMD=7ee478002bb0
Time slot  16
	CPU 0: Put process  5 to run queue
	CPU 0: Dispatched process  4
liballoc:187
print_pgtbl (PID 6):
 PDG=7ee47c00fb30 P4g=7ee474004c90 PUD=7ee474005ca0 PMD=7ee474006cb0
	CPU 2: Put process  3 to run queue
	CPU 2: Dispatched process  5
	Loaded a process at input/proc/s2, PID: 7 PRIO: 120
Time slot  17
	CPU 1: Put process  6 to run queue
	CPU 1: Dispatched process  6
libfree:218
print_pgtbl (PID 6):
 PDG=7ee47c00fb30 P4g=7ee474004c90 PUD=7ee474005ca0 PMD=7ee474006cb0
	CPU 3: Put process  1 to run queue
	CPU 3: Dispatched process  1
	Loaded a process at input/proc/s1, PID: 8 PRIO: 0
Time slot  18
	CPU 0: Put process  4 to run queue
	CPU 0: Dispatched process  8
liballoc:187
print_pgtbl (PID 6):
 PDG=7ee47c00fb30 P4g=7ee474004c90 PUD=7ee474005ca0 PMD=7ee474006cb0
	CPU 2: Put process  5 to run queue
	CPU 2: Dispatched process  4
Time slot  19
	CPU 1: Put process  6 to run queue
	CPU 1: Dispatched process  6
libfree:218
print_pgtbl (PID 6):
 PDG=7ee47c00fb30 P4g=7ee474004c90 PUD=7ee474005ca0 PMD=7ee474006cb0
	CPU 3: Put process  1 to run queue
	CPU 3: Dispatched process  1
Time slot  20
	CPU 3: Processed  1 has finished
	CPU 3: Dispatched process  5
	CPU 2: Put process  4 to run queue
	CPU 2: Dispatched process  4
libfree:218
print_pgtbl (PID 6):
 PDG=7ee47c00fb30 P4g=7ee474004c90 PUD=7ee474005ca0 PMD=7ee474006cb0
	CPU 0: Put process  8 to run queue
	CPU 0: Dispatched process  8
Time slot  21
	CPU 1: Processed  6 has finished
	CPU 1: Dispatched process  7
Time slot  22
	CPU 3: Put process  5 to run queue
	CPU 0: Put process  8 to run queue
	CPU 3: Dispatched process  5
	CPU 0: Dispatched process  8
	CPU 2: Put process  4 to run queue
	CPU 2: Dispatched process  4
Time slot  23
	CPU 1: Put process  7 to run queue
	CPU 1: Dispatched process  7
Time slot  24
	CPU 0: Put process  8 to run queue
	CPU 0: Dispatched process  8
	CPU 2: Put process  4 to run queue
	CPU 3: Put process  5 to run queue
	CPU 2: Dispatched process  4
	CPU 3: Dispatched process  5
Time slot  25
	CPU 2: Processed  4 has finished
	CPU 2: Dispatched process  3
libread:473
print_pgtbl (PID 3):
 PDG=7ee47c007b60 P4g=7ee478000b90 PUD=7ee478001ba0 PMD=7ee478002bb0
	CPU 1: Put process  7 to run queue
	CPU 1: Dispatched process  7
Time slot  26
libwrite:529
print_pgtbl (PID 3):
 PDG=7ee47c007b60 P4g=7ee478000b90 PUD=7ee478001ba0 PMD=7ee478002bb0
	CPU 3: Put process  5 to run queue
	CPU 3: Dispatched process  5
	CPU 0: Put process  8 to run queue
	CPU 0: Dispatched process  8
Time slot  27
	CPU 0: Processed  8 has finished
	CPU 0 stopped
	CPU 2: Put process  3 to run queue
	CPU 2: Dispatched process  3
libread:473
print_pgtbl (PID 3):
 PDG=7ee47c007b60 P4g=7ee478000b90 PUD=7ee478001ba0 PMD=7ee478002bb0
	CPU 1: Put process  7 to run queue
	CPU 1: Dispatched process  7
Time slot  28
	CPU 3: Put process  5 to run queue
	CPU 3: Dispatched process  5
Time slot  29
	CPU 1: Put process  7 to run queue
	CPU 1: Dispatched process  7
	CPU 2: Put process  3 to run queue
	CPU 2: Dispatched process  3
libfree:218
print_pgtbl (PID 3):
 PDG=7ee47c007b60 P4g=7ee478000b90 PUD=7ee478001ba0 PMD=7ee478002bb0
Time slot  30
	CPU 3: Processed  5 has finished
	CPU 3 stopped
Time slot  31
	CPU 1: Put process  7 to run queue
	CPU 1: Dispatched process  7
	CPU 2: Processed  3 has finished
	CPU 2 stopped
Time slot  32
Time slot  33
	CPU 1: Processed  7 has finished
	CPU 1 stopped
